Traceback (most recent call last):
  File "/Users/ckopel/Library/Python/3.9/lib/python/site-packages/urllib3/connectionpool.py", line 699, in urlopen
    httplib_response = self._make_request(
  File "/Users/ckopel/Library/Python/3.9/lib/python/site-packages/urllib3/connectionpool.py", line 445, in _make_request
    six.raise_from(e, None)
  File "<string>", line 3, in raise_from
  File "/Users/ckopel/Library/Python/3.9/lib/python/site-packages/urllib3/connectionpool.py", line 440, in _make_request
    httplib_response = conn.getresponse()
  File "/Applications/Xcode.app/Contents/Developer/Library/Frameworks/Python3.framework/Versions/3.9/lib/python3.9/http/client.py", line 1349, in getresponse
    response.begin()
  File "/Applications/Xcode.app/Contents/Developer/Library/Frameworks/Python3.framework/Versions/3.9/lib/python3.9/http/client.py", line 316, in begin
    version, status, reason = self._read_status()
  File "/Applications/Xcode.app/Contents/Developer/Library/Frameworks/Python3.framework/Versions/3.9/lib/python3.9/http/client.py", line 277, in _read_status
    line = str(self.fp.readline(_MAXLINE + 1), "iso-8859-1")
  File "/Applications/Xcode.app/Contents/Developer/Library/Frameworks/Python3.framework/Versions/3.9/lib/python3.9/socket.py", line 704, in readinto
    return self._sock.recv_into(b)
  File "/Applications/Xcode.app/Contents/Developer/Library/Frameworks/Python3.framework/Versions/3.9/lib/python3.9/ssl.py", line 1241, in recv_into
    return self.read(nbytes, buffer)
  File "/Applications/Xcode.app/Contents/Developer/Library/Frameworks/Python3.framework/Versions/3.9/lib/python3.9/ssl.py", line 1099, in read
    return self._sslobj.read(len, buffer)
OSError: [Errno 65] No route to host

During handling of the above exception, another exception occurred:

Traceback (most recent call last):
  File "/Users/ckopel/Library/Python/3.9/lib/python/site-packages/requests/adapters.py", line 667, in send
    resp = conn.urlopen(
  File "/Users/ckopel/Library/Python/3.9/lib/python/site-packages/urllib3/connectionpool.py", line 755, in urlopen
    retries = retries.increment(
  File "/Users/ckopel/Library/Python/3.9/lib/python/site-packages/urllib3/util/retry.py", line 532, in increment
    raise six.reraise(type(error), error, _stacktrace)
  File "/Users/ckopel/Library/Python/3.9/lib/python/site-packages/urllib3/packages/six.py", line 769, in reraise
    raise value.with_traceback(tb)
  File "/Users/ckopel/Library/Python/3.9/lib/python/site-packages/urllib3/connectionpool.py", line 699, in urlopen
    httplib_response = self._make_request(
  File "/Users/ckopel/Library/Python/3.9/lib/python/site-packages/urllib3/connectionpool.py", line 445, in _make_request
    six.raise_from(e, None)
  File "<string>", line 3, in raise_from
  File "/Users/ckopel/Library/Python/3.9/lib/python/site-packages/urllib3/connectionpool.py", line 440, in _make_request
    httplib_response = conn.getresponse()
  File "/Applications/Xcode.app/Contents/Developer/Library/Frameworks/Python3.framework/Versions/3.9/lib/python3.9/http/client.py", line 1349, in getresponse
    response.begin()
  File "/Applications/Xcode.app/Contents/Developer/Library/Frameworks/Python3.framework/Versions/3.9/lib/python3.9/http/client.py", line 316, in begin
    version, status, reason = self._read_status()
  File "/Applications/Xcode.app/Contents/Developer/Library/Frameworks/Python3.framework/Versions/3.9/lib/python3.9/http/client.py", line 277, in _read_status
    line = str(self.fp.readline(_MAXLINE + 1), "iso-8859-1")
  File "/Applications/Xcode.app/Contents/Developer/Library/Frameworks/Python3.framework/Versions/3.9/lib/python3.9/socket.py", line 704, in readinto
    return self._sock.recv_into(b)
  File "/Applications/Xcode.app/Contents/Developer/Library/Frameworks/Python3.framework/Versions/3.9/lib/python3.9/ssl.py", line 1241, in recv_into
    return self.read(nbytes, buffer)
  File "/Applications/Xcode.app/Contents/Developer/Library/Frameworks/Python3.framework/Versions/3.9/lib/python3.9/ssl.py", line 1099, in read
    return self._sslobj.read(len, buffer)
urllib3.exceptions.ProtocolError: ('Connection aborted.', OSError(65, 'No route to host'))

During handling of the above exception, another exception occurred:

Traceback (most recent call last):
  File "/Users/ckopel/Github/app_yahoo/scripts/app_ownership_pull_load.py", line 110, in <module>
    worksheet.update_acell('K2', '=IFERROR(((E2-E3)/E3),"")')
  File "/Users/ckopel/Library/Python/3.9/lib/python/site-packages/gspread/worksheet.py", line 737, in update_acell
    return self.update_cell(*(a1_to_rowcol(label)), value=value)
  File "/Users/ckopel/Library/Python/3.9/lib/python/site-packages/gspread/worksheet.py", line 754, in update_cell
    data = self.client.values_update(
  File "/Users/ckopel/Library/Python/3.9/lib/python/site-packages/gspread/http_client.py", line 173, in values_update
    r = self.request("put", url, params=params, json=body)
  File "/Users/ckopel/Library/Python/3.9/lib/python/site-packages/gspread/http_client.py", line 114, in request
    response = self.session.request(
  File "/Users/ckopel/Library/Python/3.9/lib/python/site-packages/google/auth/transport/requests.py", line 538, in request
    response = super(AuthorizedSession, self).request(
  File "/Users/ckopel/Library/Python/3.9/lib/python/site-packages/requests/sessions.py", line 589, in request
    resp = self.send(prep, **send_kwargs)
  File "/Users/ckopel/Library/Python/3.9/lib/python/site-packages/requests/sessions.py", line 703, in send
    r = adapter.send(request, **kwargs)
  File "/Users/ckopel/Library/Python/3.9/lib/python/site-packages/requests/adapters.py", line 682, in send
    raise ConnectionError(err, request=request)
requests.exceptions.ConnectionError: ('Connection aborted.', OSError(65, 'No route to host'))
Traceback (most recent call last):
  File "/Users/ckopel/Library/Python/3.9/lib/python/site-packages/urllib3/connection.py", line 174, in _new_conn
    conn = connection.create_connection(
  File "/Users/ckopel/Library/Python/3.9/lib/python/site-packages/urllib3/util/connection.py", line 73, in create_connection
    for res in socket.getaddrinfo(host, port, family, socket.SOCK_STREAM):
  File "/Applications/Xcode.app/Contents/Developer/Library/Frameworks/Python3.framework/Versions/3.9/lib/python3.9/socket.py", line 953, in getaddrinfo
    for res in _socket.getaddrinfo(host, port, family, type, proto, flags):
socket.gaierror: [Errno 8] nodename nor servname provided, or not known

During handling of the above exception, another exception occurred:

Traceback (most recent call last):
  File "/Users/ckopel/Library/Python/3.9/lib/python/site-packages/urllib3/connectionpool.py", line 699, in urlopen
    httplib_response = self._make_request(
  File "/Users/ckopel/Library/Python/3.9/lib/python/site-packages/urllib3/connectionpool.py", line 382, in _make_request
    self._validate_conn(conn)
  File "/Users/ckopel/Library/Python/3.9/lib/python/site-packages/urllib3/connectionpool.py", line 1010, in _validate_conn
    conn.connect()
  File "/Users/ckopel/Library/Python/3.9/lib/python/site-packages/urllib3/connection.py", line 358, in connect
    conn = self._new_conn()
  File "/Users/ckopel/Library/Python/3.9/lib/python/site-packages/urllib3/connection.py", line 186, in _new_conn
    raise NewConnectionError(
urllib3.exceptions.NewConnectionError: <urllib3.connection.HTTPSConnection object at 0x111474490>: Failed to establish a new connection: [Errno 8] nodename nor servname provided, or not known

During handling of the above exception, another exception occurred:

Traceback (most recent call last):
  File "/Users/ckopel/Library/Python/3.9/lib/python/site-packages/requests/adapters.py", line 667, in send
    resp = conn.urlopen(
  File "/Users/ckopel/Library/Python/3.9/lib/python/site-packages/urllib3/connectionpool.py", line 783, in urlopen
    return self.urlopen(
  File "/Users/ckopel/Library/Python/3.9/lib/python/site-packages/urllib3/connectionpool.py", line 783, in urlopen
    return self.urlopen(
  File "/Users/ckopel/Library/Python/3.9/lib/python/site-packages/urllib3/connectionpool.py", line 783, in urlopen
    return self.urlopen(
  File "/Users/ckopel/Library/Python/3.9/lib/python/site-packages/urllib3/connectionpool.py", line 755, in urlopen
    retries = retries.increment(
  File "/Users/ckopel/Library/Python/3.9/lib/python/site-packages/urllib3/util/retry.py", line 574, in increment
    raise MaxRetryError(_pool, url, error or ResponseError(cause))
urllib3.exceptions.MaxRetryError: HTTPSConnectionPool(host='oauth2.googleapis.com', port=443): Max retries exceeded with url: /token (Caused by NewConnectionError('<urllib3.connection.HTTPSConnection object at 0x111474490>: Failed to establish a new connection: [Errno 8] nodename nor servname provided, or not known'))

During handling of the above exception, another exception occurred:

Traceback (most recent call last):
  File "/Users/ckopel/Library/Python/3.9/lib/python/site-packages/google/auth/transport/requests.py", line 187, in __call__
    response = self.session.request(
  File "/Users/ckopel/Library/Python/3.9/lib/python/site-packages/requests/sessions.py", line 589, in request
    resp = self.send(prep, **send_kwargs)
  File "/Users/ckopel/Library/Python/3.9/lib/python/site-packages/requests/sessions.py", line 703, in send
    r = adapter.send(request, **kwargs)
  File "/Users/ckopel/Library/Python/3.9/lib/python/site-packages/requests/adapters.py", line 700, in send
    raise ConnectionError(e, request=request)
requests.exceptions.ConnectionError: HTTPSConnectionPool(host='oauth2.googleapis.com', port=443): Max retries exceeded with url: /token (Caused by NewConnectionError('<urllib3.connection.HTTPSConnection object at 0x111474490>: Failed to establish a new connection: [Errno 8] nodename nor servname provided, or not known'))

The above exception was the direct cause of the following exception:

Traceback (most recent call last):
  File "/Users/ckopel/Github/app_yahoo/scripts/app_ownership_pull_load.py", line 95, in <module>
    sh = gc.open("APP Ownership")
  File "/Users/ckopel/Library/Python/3.9/lib/python/site-packages/gspread/client.py", line 132, in open
    spreadsheet_files, response = self._list_spreadsheet_files(title, folder_id)
  File "/Users/ckopel/Library/Python/3.9/lib/python/site-packages/gspread/client.py", line 105, in _list_spreadsheet_files
    response = self.http_client.request("get", url, params=params)
  File "/Users/ckopel/Library/Python/3.9/lib/python/site-packages/gspread/http_client.py", line 114, in request
    response = self.session.request(
  File "/Users/ckopel/Library/Python/3.9/lib/python/site-packages/google/auth/transport/requests.py", line 534, in request
    self.credentials.before_request(auth_request, method, url, request_headers)
  File "/Users/ckopel/Library/Python/3.9/lib/python/site-packages/google/auth/credentials.py", line 239, in before_request
    self._blocking_refresh(request)
  File "/Users/ckopel/Library/Python/3.9/lib/python/site-packages/google/auth/credentials.py", line 202, in _blocking_refresh
    self.refresh(request)
  File "/Users/ckopel/Library/Python/3.9/lib/python/site-packages/google/oauth2/service_account.py", line 448, in refresh
    access_token, expiry, _ = _client.jwt_grant(
  File "/Users/ckopel/Library/Python/3.9/lib/python/site-packages/google/oauth2/_client.py", line 298, in jwt_grant
    response_data = _token_endpoint_request(
  File "/Users/ckopel/Library/Python/3.9/lib/python/site-packages/google/oauth2/_client.py", line 258, in _token_endpoint_request
    response_status_ok, response_data, retryable_error = _token_endpoint_request_no_throw(
  File "/Users/ckopel/Library/Python/3.9/lib/python/site-packages/google/oauth2/_client.py", line 191, in _token_endpoint_request_no_throw
    response = request(
  File "/Users/ckopel/Library/Python/3.9/lib/python/site-packages/google/auth/transport/requests.py", line 193, in __call__
    raise new_exc from caught_exc
google.auth.exceptions.TransportError: HTTPSConnectionPool(host='oauth2.googleapis.com', port=443): Max retries exceeded with url: /token (Caused by NewConnectionError('<urllib3.connection.HTTPSConnection object at 0x111474490>: Failed to establish a new connection: [Errno 8] nodename nor servname provided, or not known'))
Job started at: Mon Dec  9 16:15:41 MST 2024
Job completed at: Mon Dec  9 16:29:09 MST 2024
Job started at: Tue Dec 10 14:17:05 MST 2024
Job completed at: Tue Dec 10 14:18:35 MST 2024
Job started at: Wed Dec 11 14:17:05 MST 2024
Job completed at: Wed Dec 11 14:17:36 MST 2024
Job started at: Thu Dec 12 14:17:05 MST 2024
Error sending stats to Plausible: error sending request for url (https://plausible.io/api/event)
Job completed at: Thu Dec 12 14:17:36 MST 2024
Job started at: Thu Dec 12 16:34:19 MST 2024
Job completed at: Thu Dec 12 16:36:04 MST 2024
No network connection at: Fri Dec 13 14:31:38 MST 2024. Job skipped.
Job started at: Fri Dec 13 17:42:51 MST 2024
Job completed at: Fri Dec 13 17:43:06 MST 2024
Job started at: Sat Dec 14 14:20:46 MST 2024
Job completed at: Sat Dec 14 15:10:50 MST 2024
Job started at: Sun Dec 15 14:20:58 MST 2024
Job completed at: Sun Dec 15 14:44:20 MST 2024
Job started at: Mon Dec 16 14:44:04 MST 2024
Job completed at: Mon Dec 16 14:44:33 MST 2024
Job started at: Tue Dec 17 14:37:10 MST 2024
Job completed at: Tue Dec 17 14:39:00 MST 2024
Job started at: Wed Dec 18 14:17:00 MST 2024
Job completed at: Wed Dec 18 14:17:27 MST 2024
Job started at: Thu Dec 19 16:15:41 MST 2024
Traceback (most recent call last):
  File "/Users/ckopel/Github/app_yahoo/scripts/app_ownership_pull_load.py", line 32, in <module>
    driver.get(app_url)
  File "/Users/ckopel/Library/Python/3.9/lib/python/site-packages/selenium/webdriver/remote/webdriver.py", line 389, in get
    self.execute(Command.GET, {"url": url})
  File "/Users/ckopel/Library/Python/3.9/lib/python/site-packages/selenium/webdriver/remote/webdriver.py", line 380, in execute
    self.error_handler.check_response(response)
  File "/Users/ckopel/Library/Python/3.9/lib/python/site-packages/selenium/webdriver/remote/errorhandler.py", line 229, in check_response
    raise exception_class(message, screen, stacktrace)
selenium.common.exceptions.WebDriverException: Message: disconnected: Unable to receive message from renderer
  (failed to check if window was closed: disconnected: not connected to DevTools)
  (Session info: chrome=131.0.6778.140)
Stacktrace:
0   chromedriver                        0x0000000102937268 chromedriver + 7098984
1   chromedriver                        0x000000010292f13a chromedriver + 7065914
2   chromedriver                        0x00000001022d3d70 chromedriver + 400752
3   chromedriver                        0x00000001022bbd83 chromedriver + 302467
4   chromedriver                        0x00000001022bbabb chromedriver + 301755
5   chromedriver                        0x00000001022baa07 chromedriver + 297479
6   chromedriver                        0x00000001022e0a72 chromedriver + 453234
7   chromedriver                        0x00000001023664fc chromedriver + 1000700
8   chromedriver                        0x0000000102346fb3 chromedriver + 872371
9   chromedriver                        0x00000001023155c2 chromedriver + 669122
10  chromedriver                        0x000000010231659e chromedriver + 673182
11  chromedriver                        0x00000001028fc020 chromedriver + 6856736
12  chromedriver                        0x0000000102900050 chromedriver + 6873168
13  chromedriver                        0x00000001028de3d7 chromedriver + 6734807
14  chromedriver                        0x00000001029009ee chromedriver + 6875630
15  chromedriver                        0x00000001028cdc14 chromedriver + 6667284
16  chromedriver                        0x000000010291d778 chromedriver + 6993784
17  chromedriver                        0x000000010291d936 chromedriver + 6994230
18  chromedriver                        0x000000010292ed18 chromedriver + 7064856
19  libsystem_pthread.dylib             0x00007ff804f1a253 _pthread_start + 99
20  libsystem_pthread.dylib             0x00007ff804f15bef thread_start + 15

Job started at: Fri Dec 20 08:12:51 MST 2024
Job completed at: Fri Dec 20 08:13:21 MST 2024
No network connection at: Fri Dec 20 16:15:39 MST 2024. Job skipped.
Job started at: Fri Dec 20 17:39:38 MST 2024
Job completed at: Fri Dec 20 17:39:46 MST 2024
Traceback (most recent call last):
  File "/Users/ckopel/Github/app_yahoo/scripts/app_ownership_pull_load.py", line 73, in <module>
    stock_price = price_element['data-value']
  File "/Users/ckopel/Library/Python/3.9/lib/python/site-packages/bs4/element.py", line 1573, in __getitem__
    return self.attrs[key]
KeyError: 'data-value'
Job started at: Sun Dec 22 23:08:31 MST 2024
Job completed at: Sun Dec 22 23:10:06 MST 2024
Job started at: Mon Dec 23 14:17:02 MST 2024
Job completed at: Mon Dec 23 14:18:36 MST 2024
Job started at: Tue Dec 24 14:45:52 MST 2024
Job started at: Thu Dec 26 15:44:04 MST 2024
Job completed at: Thu Dec 26 15:45:41 MST 2024
Job started at: Fri Dec 27 14:43:16 MST 2024
Job completed at: Fri Dec 27 14:44:48 MST 2024
No network connection at: Sat Dec 28 14:23:51 MST 2024. Job skipped.
Job started at: Sun Dec 29 14:17:58 MST 2024
Job completed at: Sun Dec 29 16:50:03 MST 2024
No network connection at: Mon Dec 30 16:15:40 MST 2024. Job skipped.
Job started at: Tue Dec 31 16:15:39 MST 2024
Job completed at: Tue Dec 31 17:16:49 MST 2024
Job started at: Wed Jan  1 14:59:54 MST 2025
Job completed at: Wed Jan  1 15:00:21 MST 2025
No network connection at: Thu Jan  2 14:17:12 MST 2025. Job skipped.
Job started at: Thu Jan  2 16:04:01 MST 2025
Job completed at: Thu Jan  2 16:05:36 MST 2025
Job started at: Fri Jan  3 15:01:36 MST 2025
Job completed at: Fri Jan  3 15:02:03 MST 2025
Job started at: Sat Jan  4 14:52:09 MST 2025
Job completed at: Sat Jan  4 18:18:32 MST 2025
Job started at: Sun Jan  5 14:33:52 MST 2025
Traceback (most recent call last):
  File "/Users/ckopel/Library/Python/3.9/lib/python/site-packages/urllib3/connection.py", line 174, in _new_conn
    conn = connection.create_connection(
  File "/Users/ckopel/Library/Python/3.9/lib/python/site-packages/urllib3/util/connection.py", line 73, in create_connection
    for res in socket.getaddrinfo(host, port, family, socket.SOCK_STREAM):
  File "/Applications/Xcode.app/Contents/Developer/Library/Frameworks/Python3.framework/Versions/3.9/lib/python3.9/socket.py", line 953, in getaddrinfo
    for res in _socket.getaddrinfo(host, port, family, type, proto, flags):
socket.gaierror: [Errno 8] nodename nor servname provided, or not known

During handling of the above exception, another exception occurred:

Traceback (most recent call last):
  File "/Users/ckopel/Library/Python/3.9/lib/python/site-packages/urllib3/connectionpool.py", line 699, in urlopen
    httplib_response = self._make_request(
  File "/Users/ckopel/Library/Python/3.9/lib/python/site-packages/urllib3/connectionpool.py", line 382, in _make_request
    self._validate_conn(conn)
  File "/Users/ckopel/Library/Python/3.9/lib/python/site-packages/urllib3/connectionpool.py", line 1010, in _validate_conn
    conn.connect()
  File "/Users/ckopel/Library/Python/3.9/lib/python/site-packages/urllib3/connection.py", line 358, in connect
    conn = self._new_conn()
  File "/Users/ckopel/Library/Python/3.9/lib/python/site-packages/urllib3/connection.py", line 186, in _new_conn
    raise NewConnectionError(
urllib3.exceptions.NewConnectionError: <urllib3.connection.HTTPSConnection object at 0x10cf0e3a0>: Failed to establish a new connection: [Errno 8] nodename nor servname provided, or not known

During handling of the above exception, another exception occurred:

Traceback (most recent call last):
  File "/Users/ckopel/Library/Python/3.9/lib/python/site-packages/requests/adapters.py", line 667, in send
    resp = conn.urlopen(
  File "/Users/ckopel/Library/Python/3.9/lib/python/site-packages/urllib3/connectionpool.py", line 783, in urlopen
    return self.urlopen(
  File "/Users/ckopel/Library/Python/3.9/lib/python/site-packages/urllib3/connectionpool.py", line 783, in urlopen
    return self.urlopen(
  File "/Users/ckopel/Library/Python/3.9/lib/python/site-packages/urllib3/connectionpool.py", line 783, in urlopen
    return self.urlopen(
  File "/Users/ckopel/Library/Python/3.9/lib/python/site-packages/urllib3/connectionpool.py", line 755, in urlopen
    retries = retries.increment(
  File "/Users/ckopel/Library/Python/3.9/lib/python/site-packages/urllib3/util/retry.py", line 574, in increment
    raise MaxRetryError(_pool, url, error or ResponseError(cause))
urllib3.exceptions.MaxRetryError: HTTPSConnectionPool(host='oauth2.googleapis.com', port=443): Max retries exceeded with url: /token (Caused by NewConnectionError('<urllib3.connection.HTTPSConnection object at 0x10cf0e3a0>: Failed to establish a new connection: [Errno 8] nodename nor servname provided, or not known'))

During handling of the above exception, another exception occurred:

Traceback (most recent call last):
  File "/Users/ckopel/Library/Python/3.9/lib/python/site-packages/google/auth/transport/requests.py", line 187, in __call__
    response = self.session.request(
  File "/Users/ckopel/Library/Python/3.9/lib/python/site-packages/requests/sessions.py", line 589, in request
    resp = self.send(prep, **send_kwargs)
  File "/Users/ckopel/Library/Python/3.9/lib/python/site-packages/requests/sessions.py", line 703, in send
    r = adapter.send(request, **kwargs)
  File "/Users/ckopel/Library/Python/3.9/lib/python/site-packages/requests/adapters.py", line 700, in send
    raise ConnectionError(e, request=request)
requests.exceptions.ConnectionError: HTTPSConnectionPool(host='oauth2.googleapis.com', port=443): Max retries exceeded with url: /token (Caused by NewConnectionError('<urllib3.connection.HTTPSConnection object at 0x10cf0e3a0>: Failed to establish a new connection: [Errno 8] nodename nor servname provided, or not known'))

The above exception was the direct cause of the following exception:

Traceback (most recent call last):
  File "/Users/ckopel/Github/app_yahoo/scripts/app_ownership_pull_load.py", line 95, in <module>
    sh = gc.open("APP Ownership")
  File "/Users/ckopel/Library/Python/3.9/lib/python/site-packages/gspread/client.py", line 132, in open
    spreadsheet_files, response = self._list_spreadsheet_files(title, folder_id)
  File "/Users/ckopel/Library/Python/3.9/lib/python/site-packages/gspread/client.py", line 105, in _list_spreadsheet_files
    response = self.http_client.request("get", url, params=params)
  File "/Users/ckopel/Library/Python/3.9/lib/python/site-packages/gspread/http_client.py", line 114, in request
    response = self.session.request(
  File "/Users/ckopel/Library/Python/3.9/lib/python/site-packages/google/auth/transport/requests.py", line 534, in request
    self.credentials.before_request(auth_request, method, url, request_headers)
  File "/Users/ckopel/Library/Python/3.9/lib/python/site-packages/google/auth/credentials.py", line 239, in before_request
    self._blocking_refresh(request)
  File "/Users/ckopel/Library/Python/3.9/lib/python/site-packages/google/auth/credentials.py", line 202, in _blocking_refresh
    self.refresh(request)
  File "/Users/ckopel/Library/Python/3.9/lib/python/site-packages/google/oauth2/service_account.py", line 448, in refresh
    access_token, expiry, _ = _client.jwt_grant(
  File "/Users/ckopel/Library/Python/3.9/lib/python/site-packages/google/oauth2/_client.py", line 298, in jwt_grant
    response_data = _token_endpoint_request(
  File "/Users/ckopel/Library/Python/3.9/lib/python/site-packages/google/oauth2/_client.py", line 258, in _token_endpoint_request
    response_status_ok, response_data, retryable_error = _token_endpoint_request_no_throw(
  File "/Users/ckopel/Library/Python/3.9/lib/python/site-packages/google/oauth2/_client.py", line 191, in _token_endpoint_request_no_throw
    response = request(
  File "/Users/ckopel/Library/Python/3.9/lib/python/site-packages/google/auth/transport/requests.py", line 193, in __call__
    raise new_exc from caught_exc
google.auth.exceptions.TransportError: HTTPSConnectionPool(host='oauth2.googleapis.com', port=443): Max retries exceeded with url: /token (Caused by NewConnectionError('<urllib3.connection.HTTPSConnection object at 0x10cf0e3a0>: Failed to establish a new connection: [Errno 8] nodename nor servname provided, or not known'))
Job started at: Mon Jan  6 14:20:47 MST 2025
Job completed at: Mon Jan  6 15:08:03 MST 2025
Job started at: Tue Jan  7 14:28:22 MST 2025
Job completed at: Tue Jan  7 14:30:33 MST 2025
Job started at: Wed Jan  8 15:22:52 MST 2025
Job started at: Wed Jan  8 18:34:27 MST 2025
Job completed at: Wed Jan  8 18:34:48 MST 2025
No network connection at: Thu Jan  9 16:15:38 MST 2025. Job skipped.
Job started at: Thu Jan  9 18:29:58 MST 2025
Job completed at: Thu Jan  9 18:30:28 MST 2025
Job started at: Fri Jan 10 16:15:44 MST 2025
Traceback (most recent call last):
  File "/Users/ckopel/Github/app_yahoo/scripts/app_ownership_pull_load.py", line 73, in <module>
    stock_price = price_element['data-value']
TypeError: 'NoneType' object is not subscriptable
Job started at: Fri Jan 10 23:35:58 MST 2025
Traceback (most recent call last):
  File "/Users/ckopel/Github/app_yahoo/scripts/app_ownership_pull_load.py", line 73, in <module>
    stock_price = price_element['data-value']
TypeError: 'NoneType' object is not subscriptable
Job started at: Sat Jan 11 14:17:53 MST 2025
Traceback (most recent call last):
  File "/Users/ckopel/Github/app_yahoo/scripts/app_ownership_pull_load.py", line 60, in <module>
    value = int(value)
ValueError: invalid literal for int() with base 10: '1,000'
Job started at: Sun Jan 12 10:14:47 MST 2025
Job completed at: Sun Jan 12 10:16:28 MST 2025
