Job started at: Thu Nov 21 14:16:38 MST 2024
Traceback (most recent call last):
  File "/Users/ckopel/Github/app_yahoo/scripts/app_ownership_pull_load.py", line 32, in <module>
    driver.get(app_url)
  File "/Users/ckopel/Library/Python/3.9/lib/python/site-packages/selenium/webdriver/remote/webdriver.py", line 389, in get
    self.execute(Command.GET, {"url": url})
  File "/Users/ckopel/Library/Python/3.9/lib/python/site-packages/selenium/webdriver/remote/webdriver.py", line 380, in execute
    self.error_handler.check_response(response)
  File "/Users/ckopel/Library/Python/3.9/lib/python/site-packages/selenium/webdriver/remote/errorhandler.py", line 229, in check_response
    raise exception_class(message, screen, stacktrace)
selenium.common.exceptions.WebDriverException: Message: disconnected: Unable to receive message from renderer
  (failed to check if window was closed: disconnected: not connected to DevTools)
  (Session info: chrome=131.0.6778.85)
Stacktrace:
0   chromedriver                        0x000000010bb56e82 chromedriver + 6696578
1   chromedriver                        0x000000010bb4ec9a chromedriver + 6663322
2   chromedriver                        0x000000010b556e3e chromedriver + 405054
3   chromedriver                        0x000000010b53e91a chromedriver + 305434
4   chromedriver                        0x000000010b53e638 chromedriver + 304696
5   chromedriver                        0x000000010b53d6a5 chromedriver + 300709
6   chromedriver                        0x000000010b5642d1 chromedriver + 459473
7   chromedriver                        0x000000010b5ef7a6 chromedriver + 1030054
8   chromedriver                        0x000000010b5cc613 chromedriver + 886291
9   chromedriver                        0x000000010b599950 chromedriver + 678224
10  chromedriver                        0x000000010b59a34e chromedriver + 680782
11  chromedriver                        0x000000010bb24770 chromedriver + 6489968
12  chromedriver                        0x000000010bb27219 chromedriver + 6500889
13  chromedriver                        0x000000010bb26d3b chromedriver + 6499643
14  chromedriver                        0x000000010bb276a5 chromedriver + 6502053
15  chromedriver                        0x000000010bb0f524 chromedriver + 6403364
16  chromedriver                        0x000000010bb2798f chromedriver + 6502799
17  chromedriver                        0x000000010bb00954 chromedriver + 6342996
18  chromedriver                        0x000000010bb3f378 chromedriver + 6599544
19  chromedriver                        0x000000010bb3f535 chromedriver + 6599989
20  chromedriver                        0x000000010bb4e868 chromedriver + 6662248
21  libsystem_pthread.dylib             0x00007ff811cc518b _pthread_start + 99
22  libsystem_pthread.dylib             0x00007ff811cc0ae3 thread_start + 15

Job started at: Thu Nov 21 14:41:54 MST 2024
Job completed at: Thu Nov 21 14:42:16 MST 2024
Job started at: Fri Nov 22 14:17:00 MST 2024
Job completed at: Fri Nov 22 14:18:37 MST 2024
Job started at: Sat Nov 23 14:17:00 MST 2024
Job completed at: Sat Nov 23 14:17:16 MST 2024
Job started at: Sun Nov 24 14:17:05 MST 2024
Job completed at: Sun Nov 24 14:17:24 MST 2024
Job started at: Mon Nov 25 14:45:53 MST 2024
Job completed at: Mon Nov 25 14:47:45 MST 2024
Job started at: Tue Nov 26 14:24:23 MST 2024
Job completed at: Tue Nov 26 14:25:01 MST 2024
Job started at: Thu Nov 28 16:15:45 MST 2024
Job completed at: Thu Nov 28 18:17:53 MST 2024
Job started at: Fri Nov 29 14:45:12 MST 2024
Error sending stats to Plausible: error sending request for url (https://plausible.io/api/event)
Job completed at: Fri Nov 29 14:45:45 MST 2024
Job started at: Sat Nov 30 15:45:11 MST 2024
Job completed at: Sat Nov 30 15:47:49 MST 2024
Job started at: Sun Dec  1 16:15:47 MST 2024
There was an error managing chromedriver (error decoding response body); using driver found in the cache
Job completed at: Sun Dec  1 23:10:09 MST 2024
Job started at: Mon Dec  2 14:35:18 MST 2024
Job completed at: Mon Dec  2 14:47:09 MST 2024
Traceback (most recent call last):
  File "/Users/ckopel/Library/Python/3.9/lib/python/site-packages/urllib3/connectionpool.py", line 699, in urlopen
    httplib_response = self._make_request(
  File "/Users/ckopel/Library/Python/3.9/lib/python/site-packages/urllib3/connectionpool.py", line 445, in _make_request
    six.raise_from(e, None)
  File "<string>", line 3, in raise_from
  File "/Users/ckopel/Library/Python/3.9/lib/python/site-packages/urllib3/connectionpool.py", line 440, in _make_request
    httplib_response = conn.getresponse()
  File "/Applications/Xcode.app/Contents/Developer/Library/Frameworks/Python3.framework/Versions/3.9/lib/python3.9/http/client.py", line 1349, in getresponse
    response.begin()
  File "/Applications/Xcode.app/Contents/Developer/Library/Frameworks/Python3.framework/Versions/3.9/lib/python3.9/http/client.py", line 316, in begin
    version, status, reason = self._read_status()
  File "/Applications/Xcode.app/Contents/Developer/Library/Frameworks/Python3.framework/Versions/3.9/lib/python3.9/http/client.py", line 277, in _read_status
    line = str(self.fp.readline(_MAXLINE + 1), "iso-8859-1")
  File "/Applications/Xcode.app/Contents/Developer/Library/Frameworks/Python3.framework/Versions/3.9/lib/python3.9/socket.py", line 704, in readinto
    return self._sock.recv_into(b)
  File "/Applications/Xcode.app/Contents/Developer/Library/Frameworks/Python3.framework/Versions/3.9/lib/python3.9/ssl.py", line 1241, in recv_into
    return self.read(nbytes, buffer)
  File "/Applications/Xcode.app/Contents/Developer/Library/Frameworks/Python3.framework/Versions/3.9/lib/python3.9/ssl.py", line 1099, in read
    return self._sslobj.read(len, buffer)
ConnectionResetError: [Errno 54] Connection reset by peer

During handling of the above exception, another exception occurred:

Traceback (most recent call last):
  File "/Users/ckopel/Library/Python/3.9/lib/python/site-packages/requests/adapters.py", line 667, in send
    resp = conn.urlopen(
  File "/Users/ckopel/Library/Python/3.9/lib/python/site-packages/urllib3/connectionpool.py", line 755, in urlopen
    retries = retries.increment(
  File "/Users/ckopel/Library/Python/3.9/lib/python/site-packages/urllib3/util/retry.py", line 532, in increment
    raise six.reraise(type(error), error, _stacktrace)
  File "/Users/ckopel/Library/Python/3.9/lib/python/site-packages/urllib3/packages/six.py", line 769, in reraise
    raise value.with_traceback(tb)
  File "/Users/ckopel/Library/Python/3.9/lib/python/site-packages/urllib3/connectionpool.py", line 699, in urlopen
    httplib_response = self._make_request(
  File "/Users/ckopel/Library/Python/3.9/lib/python/site-packages/urllib3/connectionpool.py", line 445, in _make_request
    six.raise_from(e, None)
  File "<string>", line 3, in raise_from
  File "/Users/ckopel/Library/Python/3.9/lib/python/site-packages/urllib3/connectionpool.py", line 440, in _make_request
    httplib_response = conn.getresponse()
  File "/Applications/Xcode.app/Contents/Developer/Library/Frameworks/Python3.framework/Versions/3.9/lib/python3.9/http/client.py", line 1349, in getresponse
    response.begin()
  File "/Applications/Xcode.app/Contents/Developer/Library/Frameworks/Python3.framework/Versions/3.9/lib/python3.9/http/client.py", line 316, in begin
    version, status, reason = self._read_status()
  File "/Applications/Xcode.app/Contents/Developer/Library/Frameworks/Python3.framework/Versions/3.9/lib/python3.9/http/client.py", line 277, in _read_status
    line = str(self.fp.readline(_MAXLINE + 1), "iso-8859-1")
  File "/Applications/Xcode.app/Contents/Developer/Library/Frameworks/Python3.framework/Versions/3.9/lib/python3.9/socket.py", line 704, in readinto
    return self._sock.recv_into(b)
  File "/Applications/Xcode.app/Contents/Developer/Library/Frameworks/Python3.framework/Versions/3.9/lib/python3.9/ssl.py", line 1241, in recv_into
    return self.read(nbytes, buffer)
  File "/Applications/Xcode.app/Contents/Developer/Library/Frameworks/Python3.framework/Versions/3.9/lib/python3.9/ssl.py", line 1099, in read
    return self._sslobj.read(len, buffer)
urllib3.exceptions.ProtocolError: ('Connection aborted.', ConnectionResetError(54, 'Connection reset by peer'))

During handling of the above exception, another exception occurred:

Traceback (most recent call last):
  File "/Users/ckopel/Github/app_yahoo/scripts/app_ownership_pull_load.py", line 95, in <module>
    sh = gc.open("APP Ownership")
  File "/Users/ckopel/Library/Python/3.9/lib/python/site-packages/gspread/client.py", line 132, in open
    spreadsheet_files, response = self._list_spreadsheet_files(title, folder_id)
  File "/Users/ckopel/Library/Python/3.9/lib/python/site-packages/gspread/client.py", line 105, in _list_spreadsheet_files
    response = self.http_client.request("get", url, params=params)
  File "/Users/ckopel/Library/Python/3.9/lib/python/site-packages/gspread/http_client.py", line 114, in request
    response = self.session.request(
  File "/Users/ckopel/Library/Python/3.9/lib/python/site-packages/google/auth/transport/requests.py", line 538, in request
    response = super(AuthorizedSession, self).request(
  File "/Users/ckopel/Library/Python/3.9/lib/python/site-packages/requests/sessions.py", line 589, in request
    resp = self.send(prep, **send_kwargs)
  File "/Users/ckopel/Library/Python/3.9/lib/python/site-packages/requests/sessions.py", line 703, in send
    r = adapter.send(request, **kwargs)
  File "/Users/ckopel/Library/Python/3.9/lib/python/site-packages/requests/adapters.py", line 682, in send
    raise ConnectionError(err, request=request)
requests.exceptions.ConnectionError: ('Connection aborted.', ConnectionResetError(54, 'Connection reset by peer'))
Error sending stats to Plausible: error sending request for url (https://plausible.io/api/event)
There was an error managing chromedriver (error sending request for url (https://googlechromelabs.github.io/chrome-for-testing/known-good-versions-with-downloads.json)); using driver found in the cache
Error sending stats to Plausible: error sending request for url (https://plausible.io/api/event)
Traceback (most recent call last):
  File "/Users/ckopel/Github/app_yahoo/scripts/app_ownership_pull_load.py", line 32, in <module>
    driver.get(app_url)
  File "/Users/ckopel/Library/Python/3.9/lib/python/site-packages/selenium/webdriver/remote/webdriver.py", line 389, in get
    self.execute(Command.GET, {"url": url})
  File "/Users/ckopel/Library/Python/3.9/lib/python/site-packages/selenium/webdriver/remote/webdriver.py", line 380, in execute
    self.error_handler.check_response(response)
  File "/Users/ckopel/Library/Python/3.9/lib/python/site-packages/selenium/webdriver/remote/errorhandler.py", line 229, in check_response
    raise exception_class(message, screen, stacktrace)
selenium.common.exceptions.WebDriverException: Message: unknown error: net::ERR_INTERNET_DISCONNECTED
  (Session info: chrome=131.0.6778.109)
Stacktrace:
0   chromedriver                        0x0000000101470e82 chromedriver + 6696578
1   chromedriver                        0x0000000101468c9a chromedriver + 6663322
2   chromedriver                        0x0000000100e70e3e chromedriver + 405054
3   chromedriver                        0x0000000100e68654 chromedriver + 370260
4   chromedriver                        0x0000000100e58b81 chromedriver + 306049
5   chromedriver                        0x0000000100e5a608 chromedriver + 312840
6   chromedriver                        0x0000000100e58e3d chromedriver + 306749
7   chromedriver                        0x0000000100e586fa chromedriver + 304890
8   chromedriver                        0x0000000100e58638 chromedriver + 304696
9   chromedriver                        0x0000000100e56a1b chromedriver + 297499
10  chromedriver                        0x0000000100e56da7 chromedriver + 298407
11  chromedriver                        0x0000000100e73cf8 chromedriver + 417016
12  chromedriver                        0x0000000100f0a032 chromedriver + 1032242
13  chromedriver                        0x0000000100ee6872 chromedriver + 886898
14  chromedriver                        0x0000000100f093f4 chromedriver + 1029108
15  chromedriver                        0x0000000100ee6613 chromedriver + 886291
16  chromedriver                        0x0000000100eb3950 chromedriver + 678224
17  chromedriver                        0x0000000100eb434e chromedriver + 680782
18  chromedriver                        0x000000010143e770 chromedriver + 6489968
19  chromedriver                        0x0000000101441219 chromedriver + 6500889
20  chromedriver                        0x0000000101440d3b chromedriver + 6499643
21  chromedriver                        0x00000001014416a5 chromedriver + 6502053
22  chromedriver                        0x0000000101429524 chromedriver + 6403364
23  chromedriver                        0x000000010144198f chromedriver + 6502799
24  chromedriver                        0x000000010141a954 chromedriver + 6342996
25  chromedriver                        0x0000000101459378 chromedriver + 6599544
26  chromedriver                        0x0000000101459535 chromedriver + 6599989
27  chromedriver                        0x0000000101468868 chromedriver + 6662248
28  libsystem_pthread.dylib             0x00007ff804f1a253 _pthread_start + 99
29  libsystem_pthread.dylib             0x00007ff804f15bef thread_start + 15

